# 예외처리

프로그램 실행 중 코드를 잘못작성하는 것 외에 예상치 못하게 예외가 발생할 상황을 대비할 수 있는 기능, 사용자 입력값을 받는 경우 코드 실행에 문제가 될 값을 예측하기 어렵다. 

~~~ 
try:
		실행할 명령
except:
		오류 처리문
else:
		예외가 발생하지 않았을때 처리
~~~

try블럭의 코드를 실행하다가 예외가 발생하면 except블럭으로 넘어간다. 예외가 발생하지 않을 시 except블럭은 무시되고 다음 문장 실행. 

예외를 loop로 감싸면 사용자에게 입력을 조건에 맞게 할 때 까지 시도할 기회를 줄 수 있다. 

~~~ python
while True:
		str = input("점수를 입력하세요: ")
		try:
				score = int(str)
				print("입력한 점수 :", score)
				break    #try구문이 정상실행될 경우 break로 loop종료, except문은 무시하고 다음 작업인 print("성공")실행
		except:
				print("올바른 점수형식으로 입력하세요")
print("성공")
~~~



## 예외의 종류

| 예외              | 설명                                                   |
| ----------------- | ------------------------------------------------------ |
| NameError         | undefined다 초기화 되지 않은 변수를 사용하면 발생      |
| ValueError        | 값의 타입은 맞지만 형식이 잘못되었다.                  |
| ZeroDivisionError | 0으로 나누었을때 에러 발생.                            |
| IndexError        | 첨자 범위 벗어남 , len(str)이 2인데 str[5]를 읽을 경우 |
| TypeError         | 타입안맞음, int대신 str을 사용한 경우 등               |

try블럭에서 다른 종류의 예외가 발생할 경우를 대비해 예외별로 except구문을 여러개 작성하면 각 예외에 맞는 실행을 다르게 해줄 수 있다. 

마찬가지로 예외가 발생하지 않으면 다음 코드로 넘어간다. 블럭이 아무리 많아도 예외에 맞는 구문 하나만 선택되어 실행. 

예외를 튜플로 묶어 동시에 받아 한 구문으로 실행할 수도 있다. 

~~~ 
except(ValueError, IndexError):
		print("점수의 형식이나 첨자가 잘못되었습니다.")
~~~

~~~ python
except ValueError as e:
		print(e)  >>> invalid literal for int() with base n: "~" #예외설명 메시지 출력	
~~~



## raise

예외를 고의적으로 발생시킨다. 

raise 뒤에 발생시킬 예외를 적거나 특이값을 리턴하여 인수가 잘못되었음을 보고할 수 있다. 

~~~ python
def calcsum(n):
		if n < 0:            #인자에 들어갈 수에 음수를 입력하면 에러를 발생시키도록 한다.
				raise ValueError
		sum = 0
		for i in range(n+1):
				sum = sum + i
		return sum
try:
		print("1~10의 합 = ", calcsum(10))
except ValueError:
		print("입력값 오류")
~~~



## finally

예외 발생여부와 상관없이 반드시 실행할 명령 지정, 작업완료 메시지나 파일을 close해주는 명령이 있다. 

try블럭이 정상적으로 실행될 때 또는 예외에 의해 강제로 벗어났을 때도 finally 블럭은 반드시 실행되도록 되어 있다. 함수 내부의 return문을 통해 종료 되더라도 finally문은 그전에 꼭 실행 됨. 

외부 자원을 사용하는 코드는 모두 해제에 신경을 써야 한다. 그 해제 처리를 위한 구문이다. (파일 입출력후 close하는 구문, 파일에선 with를 주로 사용)

finally가 있으면 except구문 생략 가능



## assert

프로그램 실행 중 특정 조건을 점검하기 위함

~~~ 
assert 조건, 메시지(선택)
~~~

거짓이면 AssertionError 예외 발생

~~~ python
score = 120
assert score <= 100, "점수는 100이하여야 합니다"
print(score)   #AssertionError
----------------------------------------------
if score > 100:
    raise AssertionError("점수는 100이하여야 합니다")
~~~

메시지를 통해 특정 변수에 잘못된 값이 들어갔는지 즉시 발견하고 이를 해결할 수 있다. 

문제를 조기발견 하기 위함임으로 예상되는 곳에 assert문을 작성해두면 도움이 된다. 
